Workbook

Sheet Data_Single
A1: num | B1: difficulty | C1: intent | D1: exit_status | E1: status | F1: phase4_pass | G1: judge_verdict | H1: original_cc | I1: refactored_cc | J1: cc_delta | K1: original_mi | L1: refactored_mi | M1: mi_delta | N1: duration_ms | O1: strategy_iter | P1: syntax_iter | Q1: code_unchanged | R1: gpu_peak_mb | S1: tier1_syntax | T1: tier2a_cc | U1: tier2b_boundary | V1: tier2c_intent_math | W1: tier3_judge | X1: gen_steps | Y1: avg_gen_ms | Z1: csr_pass | AA1: ber | AB1: public_passed | AC1: private_passed
A2: 1 | B2: Medium | C2: DECOMPOSE_CONDITIONAL | D2: SUCCESS | E2: PASS | H2: 8 | I2: 9 | J2: 1 | K2: 40.5 | L2: 36.95 | M2: -3.55 | N2: 20561 | Q2: False | R2: 4038 | S2: 0 | T2: 0 | U2: 0 | V2: 0 | W2: 0 | Z2: True | AA2: 1.0 | AB2: 1 | AC2: 0
A3: 9 | B3: Hard | C3: DECOMPOSE_CONDITIONAL | D3: SUCCESS | E3: PASS | H3: 12 | I3: 12 | J3: 0 | K3: 28 | L3: 25.98 | M3: -2.02 | N3: 32080 | Q3: False | R3: 4038 | S3: 0 | T3: 0 | U3: 0 | V3: 0 | W3: 0 | Z3: True | AA3: 0.0 | AB3: 0 | AC3: 0
A4: 18 | B4: Medium | C4: RENAME_SYMBOL | D4: SUCCESS | E4: PASS | H4: 4 | I4: 4 | J4: 0 | K4: 51.45 | L4: 52.4 | M4: 0.95 | N4: 14047 | Q4: False | R4: 4040 | S4: 0 | T4: 0 | U4: 0 | V4: 0 | W4: 0 | Z4: True | AA4: 1.0 | AB4: 1 | AC4: 0
A5: 23 | B5: Medium | C5: DECOMPOSE_CONDITIONAL | D5: SUCCESS | E5: PASS | H5: 3 | I5: 3 | J5: 0 | K5: 79.39 | L5: 73.64 | M5: -5.75 | N5: 7028 | Q5: False | R5: 4040 | S5: 0 | T5: 0 | U5: 0 | V5: 0 | W5: 0 | Z5: True | AA5: 1.0 | AB5: 1 | AC5: 0
A6: 29 | B6: Hard | C6: DECOMPOSE_CONDITIONAL | D6: SUCCESS | E6: PASS | H6: 11 | I6: 11 | J6: 0 | K6: 31.34 | L6: 28.61 | M6: -2.73 | N6: 33598 | Q6: False | R6: 4040 | S6: 0 | T6: 0 | U6: 0 | V6: 0 | W6: 0 | Z6: True | AA6: 0.0 | AB6: 0 | AC6: 0
A7: 37 | B7: Medium | C7: EXTRACT_METHOD | D7: SUCCESS | E7: PASS | H7: 4 | I7: 4 | J7: 0 | K7: 52.48 | L7: 52 | M7: -0.48 | N7: 16553 | Q7: False | R7: 4040 | S7: 0 | T7: 0 | U7: 0 | V7: 0 | W7: 0 | Z7: False | AA7: - | AB7: 0 | AC7: 0
A8: 43 | B8: Hard | C8: DECOMPOSE_CONDITIONAL | D8: SUCCESS | E8: PASS | H8: 10 | I8: 10 | J8: 0 | K8: 43.6 | L8: 39.56 | M8: -4.04 | N8: 22072 | Q8: False | R8: 4040 | S8: 0 | T8: 0 | U8: 0 | V8: 0 | W8: 0 | Z8: True | AA8: 0.0 | AB8: 0 | AC8: 0
A9: 44 | B9: Medium | C9: EXTRACT_METHOD | D9: SUCCESS | E9: PASS | H9: 3 | I9: 4 | J9: 1 | K9: 64.86 | L9: 57.24 | M9: -7.62 | N9: 14048 | Q9: False | R9: 4040 | S9: 0 | T9: 0 | U9: 0 | V9: 0 | W9: 0 | Z9: True | AA9: 0.0 | AB9: 0 | AC9: 0
A10: 54 | B10: Medium | C10: EXTRACT_METHOD | D10: SUCCESS | E10: PASS | H10: 3 | I10: 4 | J10: 1 | K10: 72.79 | L10: 66.58 | M10: -6.21 | N10: 11040 | Q10: False | R10: 4040 | S10: 0 | T10: 0 | U10: 0 | V10: 0 | W10: 0 | Z10: True | AA10: 0.0 | AB10: 0 | AC10: 0
A11: 62 | B11: Medium | C11: CONSOLIDATE_CONDITIONAL | D11: SUCCESS | E11: PASS | H11: 11 | I11: 14 | J11: 3 | K11: 37.98 | L11: 41.76 | M11: 3.78 | N11: 27584 | Q11: False | R11: 4040 | S11: 0 | T11: 0 | U11: 0 | V11: 0 | W11: 0 | Z11: True | AA11: 0.0 | AB11: 0 | AC11: 0
A12: 68 | B12: Easy | C12: DECOMPOSE_CONDITIONAL | D12: SUCCESS | E12: PASS | H12: 6 | I12: 6 | J12: 0 | K12: 55.18 | L12: 52.43 | M12: -2.75 | N12: 15547 | Q12: False | R12: 4040 | S12: 0 | T12: 0 | U12: 0 | V12: 0 | W12: 0 | Z12: True | AA12: 1.0 | AB12: 1 | AC12: 0
A13: 71 | B13: Hard | C13: RENAME_SYMBOL | D13: SUCCESS | E13: PASS | H13: 6 | I13: 6 | J13: 0 | K13: 38.66 | L13: 38.66 | M13: 0 | N13: 26585 | Q13: False | R13: 4040 | S13: 0 | T13: 0 | U13: 0 | V13: 0 | W13: 0 | Z13: True | AA13: 0.0 | AB13: 0 | AC13: 0
... A280: 2354 | B280: Hard | C280: SPLIT_LOOP | D280: SUCCESS | E280: PASS | H280: 10 | I280: 12 | J280: 2 | K280: 27.39 | L280: 23.11 | M280: -4.28 | N280: 42101 | Q280: False | R280: 4040 | S280: 0 | T280: 0 | U280: 0 | V280: 0 | W280: 0 | Z280: True | AA280: 0.0 | AB280: 0 | AC280: 0

Sheet Data_Multi
A1: num | B1: difficulty | C1: intent | D1: exit_status | E1: status | F1: phase4_pass | G1: judge_verdict | H1: original_cc | I1: refactored_cc | J1: cc_delta | K1: original_mi | L1: refactored_mi | M1: mi_delta | N1: duration_ms | O1: strategy_iter | P1: syntax_iter | Q1: code_unchanged | R1: gpu_peak_mb | S1: tier1_syntax | T1: tier2a_cc | U1: tier2b_boundary | V1: tier2c_intent_math | W1: tier3_judge | X1: gen_steps | Y1: avg_gen_ms | Z1: csr_pass | AA1: ber | AB1: public_passed | AC1: private_passed
A2: 1 | B2: Medium | C2: DECOMPOSE_CONDITIONAL | D2: SUCCESS | E2: PASS | F2: True | G2: ACCEPT | H2: 8 | I2: 8 | J2: 0 | K2: 40.5 | L2: 38.44 | M2: -2.06 | N2: 57610 | O2: 1 | P2: 0 | Q2: False | R2: 3334 | S2: 0 | T2: 0 | U2: 0 | V2: 0 | W2: 0 | X2: 2 | Y2: 8051 | Z2: False | AA2: - | AB2: 0 | AC2: 0
A3: 9 | B3: Hard | C3: DECOMPOSE_CONDITIONAL | D3: SUCCESS | E3: PASS | F3: True | G3: ACCEPT | H3: 12 | I3: 12 | J3: 0 | K3: 28 | L3: 24.86 | M3: -3.14 | N3: 116252 | O3: 1 | P3: 0 | Q3: False | R3: 3334 | S3: 0 | T3: 0 | U3: 0 | V3: 0 | W3: 0 | X3: 4 | Y3: 10240 | Z3: True | AA3: 0.0 | AB3: 0 | AC3: 0
A4: 18 | B4: Medium | C4: RENAME_SYMBOL | D4: SUCCESS | E4: PASS | F4: False | G4: ACCEPT | H4: 4 | I4: 4 | J4: 0 | K4: 51.45 | L4: 51.45 | M4: 0 | N4: 67283 | O4: 2 | P4: 0 | Q4: False | R4: 3334 | S4: 0 | T4: 0 | U4: 0 | V4: 2 | W4: 0 | X4: 2 | Y4: 4736 | Z4: True | AA4: 1.0 | AB4: 1 | AC4: 0
A5: 23 | B5: Medium | C5: DECOMPOSE_CONDITIONAL | D5: SUCCESS | E5: PASS | F5: True | G5: ACCEPT | H5: 3 | I5: 3 | J5: 0 | K5: 79.39 | L5: 73.64 | M5: -5.75 | N5: 52607 | O5: 1 | P5: 0 | Q5: False | R5: 3334 | S5: 0 | T5: 0 | U5: 0 | V5: 0 | W5: 0 | X5: 4 | Y5: 2840 | Z5: True | AA5: 1.0 | AB5: 1 | AC5: 0
A6: 29 | B6: Hard | C6: DECOMPOSE_CONDITIONAL | D6: SUCCESS | E6: PASS | F6: True | G6: ACCEPT | H6: 11 | I6: 12 | J6: 1 | K6: 31.34 | L6: 25.82 | M6: -5.52 | N6: 123183 | O6: 1 | P6: 0 | Q6: False | R6: 3334 | S6: 0 | T6: 0 | U6: 0 | V6: 0 | W6: 0 | X6: 4 | Y6: 11024 | Z6: False | AA6: - | AB6: 0 | AC6: 0
A7: 37 | B7: Medium | C7: EXTRACT_METHOD | D7: SUCCESS | E7: PASS | F7: True | G7: ACCEPT | H7: 4 | I7: 4 | J7: 0 | K7: 52.48 | L7: 46.74 | M7: -5.74 | N7: 49328 | O7: 1 | P7: 0 | Q7: False | R7: 3334 | S7: 0 | T7: 0 | U7: 0 | V7: 0 | W7: 0 | X7: 2 | Y7: 7974 | Z7: False | AA7: - | AB7: 0 | AC7: 0
A8: 43 | B8: Hard | C8: DECOMPOSE_CONDITIONAL | D8: SUCCESS | E8: PASS | F8: True | G8: ACCEPT | H8: 10 | I8: 11 | J8: 1 | K8: 43.6 | L8: 36.01 | M8: -7.59 | N8: 61819 | O8: 1 | P8: 0 | Q8: False | R8: 3334 | S8: 0 | T8: 0 | U8: 0 | V8: 0 | W8: 0 | X8: 2 | Y8: 8331 | Z8: False | AA8: - | AB8: 0 | AC8: 0
A9: 44 | B9: Medium | C9: EXTRACT_METHOD | D9: SUCCESS | E9: PASS | F9: True | G9: ACCEPT | H9: 3 | I9: 3 | J9: 0 | K9: 64.86 | L9: 59.37 | M9: -5.49 | N9: 75693 | O9: 1 | P9: 0 | Q9: False | R9: 3336 | S9: 0 | T9: 0 | U9: 0 | V9: 0 | W9: 0 | X9: 5 | Y9: 4812 | Z9: True | AA9: 0.0 | AB9: 0 | AC9: 0
A10: 54 | B10: Medium | C10: EXTRACT_METHOD | D10: SUCCESS | E10: PASS | F10: True | G10: ACCEPT | H10: 3 | I10: 3 | J10: 0 | K10: 72.79 | L10: 65.89 | M10: -6.9 | N10: 44734 | O10: 1 | P10: 0 | Q10: False | R10: 3336 | S10: 0 | T10: 0 | U10: 0 | V10: 0 | W10: 0 | X10: 2 | Y10: 3674 | Z10: True | AA10: 0.0 | AB10: 0 | AC10: 0
A11: 62 | B11: Medium | C11: CONSOLIDATE_CONDITIONAL | D11: ABORT_STRATEGY | E11: FAIL | F11: False | H11: 11 | I11: 11 | J11: 0 | K11: 37.98 | L11: 37.98 | M11: 0 | N11: 152416 | O11: 4 | P11: 0 | Q11: True | R11: 2826 | S11: 0 | T11: 0 | U11: 0 | V11: 3 | W11: 0 | X11: 0 | Z11: True | AA11: 0.0 | AB11: 0 | AC11: 0
A12: 68 | B12: Easy | C12: DECOMPOSE_CONDITIONAL | D12: SUCCESS | E12: PASS | F12: True | G12: ACCEPT | H12: 6 | I12: 6 | J12: 0 | K12: 55.18 | L12: 52.8 | M12: -2.38 | N12: 99839 | O12: 1 | P12: 0 | Q12: False | R12: 3336 | S12: 0 | T12: 0 | U12: 0 | V12: 0 | W12: 0 | X12: 4 | Y12: 5823 | Z12: True | AA12: 0.0 | AB12: 0 | AC12: 0
A13: 71 | B13: Hard | C13: RENAME_SYMBOL | D13: SUCCESS | E13: PASS | F13: False | G13: ACCEPT | H13: 6 | I13: 6 | J13: 0 | K13: 38.66 | L13: 38.66 | M13: 0 | N13: 182963 | O13: 3 | P13: 0 | Q13: False | R13: 3336 | S13: 0 | T13: 0 | U13: 0 | V13: 0 | W13: 2 | X13: 4 | Y13: 9115 | Z13: True | AA13: 0.0 | AB13: 0 | AC13: 0
A14: 72 | B14: Medium | C14: FLATTEN_CONDITIONAL | D14: SUCCESS | E14: PASS | F14: True | G14: ACCEPT | H14: 14 | I14: 15 | J14: 1 | K14: 34.58 | L14: 34.38 | M14: -0.2 | N14: 85024 | O14: 1 | P14: 0 | Q14: False | R14: 3336 | S14: 0 | T14: 0 | U14: 0 | V14: 0 | W14: 0 | X14: 0 | Z14: False | AA14: - | AB14: 0 | AC14: 0
A15: 74 | B15: Medium | C15: EXTRACT_VARIABLE | D15: ABORT_STRATEGY | E15: FAIL | F15: False | H15: 4 | I15: 4 | J15: 0 | K15: 56.35 | L15: 56.35 | M15: 0 | N15: 116807 | O15: 4 | P15: 0 | Q15: True | R15: 2826 | S15: 0 | T15: 0 | U15: 0 | V15: 3 | W15: 0 | X15: 4 | Y15: 4933 | Z15: True | AA15: 0.0 | AB15: 0 | AC15: 0
A16: 76 | B16: Medium | C16: INLINE_METHOD | D16: SUCCESS | E16: PASS | F16: True | G16: ACCEPT | H16: 3 | I16: 3 | J16: 0 | K16: 55.54 | L16: 55.54 | M16: 0 | N16: 51727 | O16: 1 | P16: 0 | Q16: False | R16: 3336 | S16: 0 | T16: 0 | U16: 0 | V16: 0 | W16: 0 | X16: 0 | Z16: True | AA16: 1.0 | AB16: 1 | AC16: 0
A17: 80 | B17: Medium | C17: FLATTEN_CONDITIONAL | D17: SUCCESS | E17: PASS | F17: False | G17: ACCEPT | H17: 9 | I17: 10 | J17: 1 | K17: 40.24 | L17: 37.29 | M17: -2.95 | N17: 127487 | O17: 2 | P17: 0 | Q17: False | R17: 3334 | S17: 0 | T17: 0 | U17: 0 | V17: 0 | W17: 1 | X17: 0 | Z17: True | AA17: 0.0 | AB17: 0 | AC17: 0
A18: 86 | B18: Hard | C18: INLINE_METHOD | D18: SUCCESS | E18: PASS | F18: True | G18: ACCEPT | H18: 8 | I18: 8 | J18: 0 | K18: 45.8 | L18: 42.03 | M18: -3.77 | N18: 57029 | O18: 1 | P18: 0 | Q18: False | R18: 3336 | S18: 0 | T18: 0 | U18: 0 | V18: 0 | W18: 0 | X18: 0 | Z18: False | AA18: - | AB18: 0 | AC18: 0
A19: 88 | B19: Medium | C19: EXTRACT_METHOD | D19: SUCCESS | E19: PASS | F19: True | G19: ACCEPT | H19: 2 | I19: 2 | J19: 0 | K19: 73.58 | L19: 66.92 | M19: -6.66 | N19: 43677 | O19: 1 | P19: 0 | Q19: False | R19: 3336 | S19: 0 | T19: 0 | U19: 0 | V19: 0 | W19: 0 | X19: 2 | Y19: 4551 | Z19: True | AA19: 1.0 | AB19: 1 | AC19: 0
A20: 96 | B20: Medium | C20: CONSOLIDATE_CONDITIONAL | D20: ABORT_STRATEGY | E20: FAIL | F20: False | H20: 11 | I20: 11 | J20: 0 | K20: 30.44 | L20: 30.44 | M20: 0 | N20: 163417 | O20: 4 | P20: 0 | Q20: True | R20: 2826 | S20: 0 | T20: 0 | U20: 0 | V20: 3 | W20: 0 | X20: 0 | Z20: True | AA20: 0.0 | AB20: 0 | AC20: 0
A21: 98 | B21: Medium | C21: FLATTEN_CONDITIONAL | D21: ABORT_STRATEGY | E21: FAIL | F21: False | G21: REVISE | H21: 5 | I21: 5 | J21: 0 | K21: 51.37 | L21: 51.37 | M21: 0 | N21: 336238 | O21: 4 | P21: 0 | Q21: True | R21: 3334 | S21: 0 | T21: 0 | U21: 2 | V21: 0 | W21: 1 | X21: 0 | Z21: True | AA21: 0.0 | AB21: 0 | AC21: 0
A22: 99 | B22: Easy | C22: DECOMPOSE_CONDITIONAL | D22: SUCCESS | E22: PASS | F22: True | G22: ACCEPT | H22: 7 | I22: 6 | J22: -1 | K22: 54.81 | L22: 60.32 | M22: 5.51 | N22: 77977 | O22: 1 | P22: 0 | Q22: False | R22: 3336 | S22: 0 | T22: 0 | U22: 0 | V22: 0 | W22: 0 | X22: 4 | Y22: 4748 | Z22: False | AA22: - | AB22: 0 | AC22: 0
A23: 106 | B23: Medium | C23: SPLIT_LOOP | D23: SUCCESS | E23: PASS | F23: True | G23: ACCEPT | H23: 6 | I23: 5 | J23: -1 | K23: 43.72 | L23: 35.21 | M23: -8.51 | N23: 84326 | O23: 1 | P23: 0 | Q23: False | R23: 3336 | S23: 0 | T23: 0 | U23: 0 | V23: 0 | W23: 0 | X23: 4 | Y23: 10535 | Z23: True | AA23: 0.0 | AB23: 0 | AC23: 0
A24: 110 | B24: Easy | C24: EXTRACT_METHOD | D24: SUCCESS | E24: PASS | F24: True | G24: ACCEPT | H24: 4 | I24: 3 | J24: -1 | K24: 74 | L24: 66.27 | M24: -7.73 | N24: 73845 | O24: 1 | P24: 0 | Q24: False | R24: 3336 | S24: 0 | T24: 0 | U24: 0 | V24: 0 | W24: 0 | X24: 4 | Y24: 5939 | Z24: True | AA24: 0.0 | AB24: 0 | AC24: 0
A25: 121 | B25: Medium | C25: EXTRACT_METHOD | D25: SUCCESS | E25: PASS | F25: True | G25: ACCEPT | H25: 3 | I25: 3 | J25: 0 | K25: 69.83 | L25: 46.93 | M25: -22.9 | N25: 41126 | O25: 1 | P25: 0 | Q25: False | R25: 3336 | S25: 0 | T25: 0 | U25: 0 | V25: 0 | W25: 0 | X25: 2 | Y25: 5446 | Z25: False | AA25: - | AB25: 0 | AC25: 0
A26: 125 | B26: Hard | C26: CONSOLIDATE_CONDITIONAL | D26: SUCCESS | E26: PASS | F26: False | G26: ACCEPT | H26: 8 | I26: 7 | J26: -1 | K26: 16.33 | L26: 16.53 | M26: 0.2 | N26: 311765 | O26: 2 | P26: 0 | Q26: False | R26: 3336 | S26: 0 | T26: 0 | U26: 1 | V26: 2 | W26: 0 | X26: 5 | Y26: 19819 | Z26: True | AA26: 0.0 | AB26: 0 | AC26: 0
A27: 131 | B27: Hard | C27: DECOMPOSE_CONDITIONAL | D27: SUCCESS | E27: PASS | F27: True | G27: ACCEPT | H27: 7 | I27: 7 | J27: 0 | K27: 45.23 | L27: 41.3 | M27: -3.93 | N27: 87583 | O27: 1 | P27: 0 | Q27: False | R27: 3336 | S27: 0 | T27: 0 | U27: 0 | V27: 0 | W27: 0 | X27: 4 | Y27: 7221 | Z27: True | AA27: 0.0 | AB27: 0 | AC27: 0
A28: 141 | B28: Medium | C28: DECOMPOSE_CONDITIONAL | D28: SUCCESS | E28: PASS | F28: True | G28: ACCEPT | H28: 5 | I28: 7 | J28: 2 | K28: 53.47 | L28: 48.61 | M28: -4.86 | N28: 74492 | O28: 1 | P28: 0 | Q28: False | R28: 3336 | S28: 0 | T28: 0 | U28: 0 | V28: 0 | W28: 0 | X28: 4 | Y28: 4568 | Z28: False | AA28: - | AB28: 0 | AC28: 0
A29: 144 | B29: Easy | C29: RENAME_SYMBOL | D29: SUCCESS | E29: PASS | F29: True | G29: ACCEPT | H29: 5 | I29: 5 | J29: 0 | K29: 51.64 | L29: 52.59 | M29: 0.95 | N29: 41893 | O29: 1 | P29: 0 | Q29: False | R29: 3336 | S29: 0 | T29: 0 | U29: 0 | V29: 0 | W29: 0 | X29: 2 | Y29: 6199 | Z29: True | AA29: 0.0 | AB29: 0 | AC29: 0
A30: 146 | B30: Medium | C30: SPLIT_LOOP | D30: SUCCESS | E30: PASS | F30: True | G30: ACCEPT | H30: 4 | I30: 4 | J30: 0 | K30: 56.09 | L30: 35.89 | M30: -20.2 | N30: 278316 | O30: 1 | P30: 0 | Q30: False | R30: 3336 | S30: 0 | T30: 0 | U30: 0 | V30: 0 | W30: 0 | X30: 4 | Y30: 59030 | Z30: False | AA30: - | AB30: 0 | AC30: 0
A31: 147 | B31: Medium | C31: DECOMPOSE_CONDITIONAL | D31: SUCCESS | E31: PASS | F31: True | G31: ACCEPT | H31: 5 | I31: 5 | J31: 0 | K31: 40.67 | L31: 37.36 | M31: -3.31 | N31: 106794 | O31: 1 | P31: 0 | Q31: False | R31: 3336 | S31: 0 | T31: 0 | U31: 0 | V31: 0 | W31: 0 | X31: 4 | Y31: 8198 | Z31: False | AA31: - | AB31: 0 | AC31: 0
A32: 151 | B32: Medium | C32: EXTRACT_VARIABLE | D32: ABORT_STRATEGY | E32: FAIL | F32: False | H32: 3 | I32: 3 | J32: 0 | K32: 51.97 | L32: 51.97 | M32: 0 | N32: 117282 | O32: 4 | P32: 0 | Q32: True | R32: 2828 | S32: 0 | T32: 1 | U32: 0 | V32: 2 | W32: 0 | X32: 5 | Y32: 5035 | Z32: True | AA32: 0.0 | AB32: 0 | AC32: 0
A33: 152 | B33: Medium | C33: INLINE_VARIABLE | D33: SUCCESS | E33: PASS | F33: True | G33: ACCEPT | H33: 3 | I33: 3 | J33: 0 | K33: 61.33 | L33: 64.28 | M33: 2.95 | N33: 42505 | O33: 1 | P33: 0 | Q33: False | R33: 3336 | S33: 0 | T33: 0 | U33: 0 | V33: 0 | W33: 0 | X33: 0 | Z33: False | AA33: - | AB33: 0 | AC33: 0
A34: 153 | B34: Hard | C34: INLINE_VARIABLE | D34: SUCCESS | E34: PASS | F34: False | G34: ACCEPT | H34: 4 | I34: 4 | J34: 0 | K34: 57.1 | L34: 59.71 | M34: 2.61 | N34: 98383 | O34: 3 | P34: 0 | Q34: False | R34: 3336 | S34: 0 | T34: 0 | U34: 0 | V34: 0 | W34: 2 | X34: 0 | Z34: False | AA34: - | AB34: 0 | AC34: 0
A35: 155 | B35: Medium | C35: DECOMPOSE_CONDITIONAL | D35: SUCCESS | E35: PASS | F35: True | G35: ACCEPT | H35: 3 | I35: 4 | J35: 1 | K35: 58.04 | L35: 49.92 | M35: -8.12 | N35: 71919 | O35: 1 | P35: 0 | Q35: False | R35: 3336 | S35: 0 | T35: 0 | U35: 0 | V35: 0 | W35: 0 | X35: 4 | Y35: 4996 | Z35: False | AA35: - | AB35: 0 | AC35: 0
A36: 160 | B36: Medium | C36: RENAME_SYMBOL | D36: ABORT_STRATEGY | E36: FAIL | F36: False | G36: REVISE | H36: 6 | I36: 6 | J36: 0 | K36: 47.42 | L36: 47.42 | M36: 0 | N36: 116837 | O36: 4 | P36: 0 | Q36: True | R36: 3336 | S36: 0 | T36: 0 | U36: 0 | V36: 1 | W36: 2 | X36: 2 | Y36: 8753 | Z36: True | AA36: 0.0 | AB36: 0 | AC36: 0
A37: 161 | B37: Medium | C37: INLINE_VARIABLE | D37: SUCCESS | E37: PASS | F37: True | G37: ACCEPT | H37: 3 | I37: 2 | J37: -1 | K37: 61.07 | L37: 92.39 | M37: 31.32 | N37: 38605 | O37: 1 | P37: 0 | Q37: False | R37: 3336 | S37: 0 | T37: 0 | U37: 0 | V37: 0 | W37: 0 | X37: 2 | Y37: 2032 | Z37: True | AA37: 0.0 | AB37: 0 | AC37: 0
A38: 164 | B38: Medium | C38: DECOMPOSE_CONDITIONAL | D38: SUCCESS | E38: PASS | F38: True | G38: ACCEPT | H38: 9 | I38: 9 | J38: 0 | K38: 47.19 | L38: 44.98 | M38: -2.21 | N38: 90291 | O38: 1 | P38: 0 | Q38: False | R38: 3336 | S38: 0 | T38: 0 | U38: 0 | V38: 0 | W38: 0 | X38: 4 | Y38: 7522 | Z38: False | AA38: - | AB38: 0 | AC38: 0
A39: 168 | B39: Easy | C39: REPLACE_LOOP_WITH_PIPELINE | D39: SUCCESS | E39: PASS | F39: True | G39: ACCEPT | H39: 4 | I39: 1 | J39: -3 | K39: 68.32 | L39: 77.36 | M39: 9.04 | N39: 57808 | O39: 1 | P39: 0 | Q39: False | R39: 3336 | S39: 0 | T39: 0 | U39: 0 | V39: 0 | W39: 0 | X39: 0 | Z39: False | AA39: - | AB39: 0 | AC39: 0
A40: 171 | B40: Medium | C40: RENAME_SYMBOL | D40: ABORT_STRATEGY | E40: FAIL | F40: False | H40: 2 | I40: 2 | J40: 0 | K40: 80.24 | L40: 80.24 | M40: 0 | N40: 73694 | O40: 4 | P40: 0 | Q40: True | R40: 2828 | S40: 0 | T40: 0 | U40: 0 | V40: 3 | W40: 0 | X40: 5 | Y40: 2660 | Z40: True | AA40: 1.0 | AB40: 1 | AC40: 0
...

Sheet Computations
A1: Table 1: Overall CSR
A2: Metric | B2: Single | C2: Multi
A3: CSR (%) | B3: =B5/B6 -> 0.67741935 | C3: =C5/C6 -> 0.58422939
A4: Compiled | B4: =COUNTIF(Data_Single!Z:Z, "True") -> 189 | C4: =COUNTIF(Data_Multi!Z:Z, "True") -> 163
A5: Total | B5: =COUNTA(Data_Single!A:A)-1 -> 279 | C5: =COUNTA(Data_Multi!A:A)-1 -> 279
A8: Table 2: Duration Statistics
A9: Metric | B9: Single (7B) | C9: Multi (3BxN)
A10: RAW mean (s) | B10: =AVERAGE(Data_Single!N:N)/1000 -> 19.470373 | C10: =AVERAGE(Data_Multi!N:N)/1000 -> 97.26233
A11: RAW median (s) | B11: =MEDIAN(Data_Single!N:N)/1000 -> 17.551 | C11: =MEDIAN(Data_Multi!N:N)/1000 -> 80.315
A12: SUCCESS mean (s) | B12: =AVERAGEIFS(Data_Single!N:N, Data_Single!D:D, "SUCCESS")/1000 -> 19.412713 | C12: =AVERAGEIFS(Data_Multi!N:N, Data_Multi!D:D, "SUCCESS")/1000 -> 80.114342
A13: Total wall time (s) | B13: =SUM(Data_Single!N:N)/1000 -> 5432.234 | C13: =SUM(Data_Multi!N:N)/1000 -> 27136.19
A16: Table 3: Peak GPU Memory
A17: Metric | B17: Single (7B) | C17: Multi (3BxN)
A18: Mean (MB) | B18: =AVERAGE(Data_Single!R:R) -> 4043.9427 | C18: =AVERAGE(Data_Multi!R:R) -> 3231.9857
A19: Median (MB) | B19: =MEDIAN(Data_Single!R:R) -> 4040 | C19: =MEDIAN(Data_Multi!R:R) -> 3336
A20: Max (MB) | B20: =MAX(Data_Single!R:R) -> 4054 | C20: =MAX(Data_Multi!R:R) -> 3336
A21: Min (MB) | B21: =MIN(Data_Single!R:R) -> 4024 | C21: =MIN(Data_Multi!R:R) -> 2826
A24: Table 4: CC Delta
A25: Metric | B25: Single | C25: Multi
A26: Mean | B26: =AVERAGE(Data_Single!J:J) -> -0.082437276 | C26: =AVERAGE(Data_Multi!J:J) -> -0.2437276
A27: Median | B27: =MEDIAN(Data_Single!J:J) -> 0 | C27: =MEDIAN(Data_Multi!J:J) -> 0
A28: Max | B28: =MAX(Data_Single!J:J) -> 9 | C28: =MAX(Data_Multi!J:J) -> 4
A29: Min | B29: =MIN(Data_Single!J:J) -> -7 | C29: =MIN(Data_Multi!J:J) -> -5
A32: Table 5: MI Delta
A33: Metric | B33: Single | C33: Multi
A34: Mean | B34: =AVERAGE(Data_Single!M:M) -> -1.6304301 | C34: =AVERAGE(Data_Multi!M:M) -> -1.5939785
A35: Median | B35: =MEDIAN(Data_Single!M:M) -> -1.87 | C35: =MEDIAN(Data_Multi!M:M) -> 0
A36: Max | B36: =MAX(Data_Single!M:M) -> 51.46 | C36: =MAX(Data_Multi!M:M) -> 32.27
A37: Min | B37: =MIN(Data_Single!M:M) -> -68.39 | C37: =MIN(Data_Multi!M:M) -> -23.01
A40: Table 6: BER
A41: Metric | B41: Single | C41: Multi
A42: Mean | B42: =AVERAGE(Data_Single!AA:AA) -> 0.11111111 | C42: =AVERAGE(Data_Multi!AA:AA) -> 0.098159509
A43: Median | B43: =MEDIAN(Data_Single!AA:AA) -> 0 | C43: =MEDIAN(Data_Multi!AA:AA) -> 0
A48: Table 7: Statistical Significance
A49: Metric | B49: Shapiro-Wilk p-value | C49: Wilcoxon p-value | D49: Significant (p < 0.05)?
A50: Duration (RAW) | B50: 9.177294e-19 | C50: 1.6589255e-47 | D50: =IF(C50<0.05, "Significant", "Not Significant") -> Significant
A51: GPU Memory (RAW) | B51: 1.1472353e-26 | C51: 3.945241e-48 | D51: =IF(C51<0.05, "Significant", "Not Significant") -> Significant
